<?xml version="1.0"?>
<robot xmlns:xacro="http://www.ros.org/wiki/xacro" name="barista_robot">

  <!-- Arguments -->
  <xacro:property name="include_laser" value="$(arg include_laser)"/>

  <!-- Included tags -->
  <xacro:include filename="$(find barista_robot_description)/xacro/cup_holder_tray.xacro"/>
  <xacro:include filename="$(find barista_robot_description)/xacro/standoff.xacro"/>
  <xacro:include filename="$(find barista_robot_description)/xacro/wheel.xacro"/>
  <xacro:include filename="$(find barista_robot_description)/xacro/laser_scanner.xacro"/>

  <!-- Global Material Definitions -->
  <material name="Red">
    <color rgba="1.0 0.0 0.0 1.0"/>
  </material>

  <material name="Blue">
    <color rgba="0.0 0.0 1.0 1.0"/>
  </material>

  <material name="Black">
    <color rgba="0.0 0.0 0.0 1.0"/>
  </material>

  <material name="Green">
    <color rgba="0.0 1.0 0.0 1.0"/>
  </material>

  <material name="LightNavyBlue">
    <color rgba="0.2 0.2 0.7 1.0"/>
  </material>

  <material name="Gray">
    <color rgba="0.5 0.5 0.5 1.0"/>
  </material>

  <material name="White">
    <color rgba="1.0 1.0 1.0 1.0"/>
  </material>

  <material name="Purple">
    <color rgba="0.5 0.0 0.5 1.0"/>
  </material>

  <material name="Yellow">
    <color rgba="1.0 1.0 0.0 1.0"/>
  </material>


  <!-- Properties -->
  <xacro:property name="body_radius" value="0.178"/>
  <xacro:property name="body_length" value="0.155"/>
  <xacro:property name="cup_holder_tray_radius" value="0.16"/>
  <xacro:property name="cup_holder_tray_length" value="0.09"/>
  <xacro:property name="standoff_rods_radius" value="0.01"/>
  <xacro:property name="standoff_rods_length" value="0.22"/>
  <xacro:property name="wheel_radius" value="0.0352"/>
  <xacro:property name="wheel_length" value="0.0206"/>
  <xacro:property name="caster_wheel_radius" value="0.02"/>
  <xacro:property name="caster_wheel_length" value="0.01"/>
  <xacro:property name="box_laser_scan_width" value="0.035"/>
  <xacro:property name="box_laser_scan_height" value="0.05"/>
  <xacro:property name="box_laser_scan_depth" value="0.035"/>

  <!-- Define base link -->
  <link name="base_link">
  </link>

  <!-- Robot Body -->
  <!-- Chassis Link -->
  <link name="chassis">
    <visual>
      <geometry>
        <cylinder length="${body_length}" radius="${body_radius}"/>
      </geometry>
      <material name="LightNavyBlue"/>
    </visual>
    <collision>
      <geometry>
        <cylinder length="${body_length}" radius="${body_radius}"/>
      </geometry>
    </collision>
    <inertial>
      <mass value="0.5"/>
      <origin xyz="0 0 0"/>
      <inertia ixx="0.004961541666666666" ixy="0.0" ixz="0.0" iyy="0.004961541666666666" iyz="0.0" izz="0.007921"/>
    </inertial>
  </link>

  <!-- Joint to Attach to Parent -->
  <joint name="chassis_joint" type="fixed">
    <origin rpy="0 0 0" xyz="0 0 0.0975"/>
    <parent link="base_link"/>
    <child link="chassis"/>
  </joint>

  <gazebo reference="chassis">
    <material>Gazebo/Blue</material>
  </gazebo>

  <!-- Cup Holder Tray -->
  <xacro:cup_holder_tray
    name="cup_holder_tray"
    radius="${cup_holder_tray_radius}"
    length="${cup_holder_tray_length}"
    material="LightNavyBlue"
    mass="0.2"
    parent_link="chassis"
    xyz="0 0 0.3425"
    rpy="0 0 0"
    joint_type="fixed"
    axis="0 0 0"/>

  <gazebo reference="cup_holder_tray">
    <material>Gazebo/Blue</material>
  </gazebo>

  <!-- Standoff Rods -->
  <xacro:standoff 
    name="standoff_rod_1"
    radius="${standoff_rods_radius}"
    length="${standoff_rods_length}"
    material="White"
    mass="0.07"
    parent_link="chassis"
    xyz="0.05 0.12 0.1875"
    rpy="0 0 0"
    joint_type="fixed"
    axis="0 0 0"/>

  <xacro:standoff 
    name="standoff_rod_2"
    radius="${standoff_rods_radius}"
    length="${standoff_rods_length}"
    material="White"
    mass="0.07"
    parent_link="chassis"
    xyz="-0.05 0.12 0.1875"
    rpy="0 0 0"
    joint_type="fixed"
    axis="0 0 0"/>
  
  <xacro:standoff 
    name="standoff_rod_3"
    radius="${standoff_rods_radius}"
    length="${standoff_rods_length}"
    material="White"
    mass="0.07"
    parent_link="chassis"
    xyz="0.05 -0.12 0.1875"
    rpy="0 0 0"
    joint_type="fixed"
    axis="0 0 0"/>
  
  <xacro:standoff
    name="standoff_rod_4"
    radius="${standoff_rods_radius}"
    length="${standoff_rods_length}"
    material="White"
    mass="0.07"
    parent_link="chassis"
    xyz="-0.05 -0.12 0.1875"
    rpy="0 0 0"
    joint_type="fixed"
    axis="0 0 0"/>

  <gazebo reference="standoff_rod_1">
    <material>Gazebo/White</material>
  </gazebo>

  <gazebo reference="standoff_rod_2">
    <material>Gazebo/White</material>
  </gazebo>
  
  <gazebo reference="standoff_rod_3">
    <material>Gazebo/White</material>
  </gazebo>
  
  <gazebo reference="standoff_rod_4">
    <material>Gazebo/White</material>
  </gazebo>

  <!-- Wheels -->
  <xacro:wheel
    name="wheel_right"
    radius="${wheel_radius}"
    length="${wheel_length}"
    material="Black"
    mass="0.1"
    parent_link="chassis"
    xyz="0 -0.12 -0.0623"
    rpy="0 1.5708 1.5708"
    joint_type="continuous"
    axis="0 0 1"/>

  <xacro:wheel
    name="wheel_left"
    radius="${wheel_radius}"
    length="${wheel_length}"
    material="Black"
    mass="0.1"
    parent_link="chassis"
    xyz="0 0.12 -0.0623"
    rpy="0 1.5708 1.5708"
    joint_type="continuous"
    axis="0 0 1"/>
  
  <!-- Gazebo configuration for Wheels -->
  <gazebo reference="wheel_right">
    <kp>1000000000000000000000000000.0</kp>
    <kd>1000000000000000000000000000.0</kd>
    <mu1>0.8</mu1>
    <mu2>0.8</mu2>
    <material>Gazebo/Black</material>
  </gazebo>

  <gazebo reference="wheel_left">
    <kp>1000000000000000000000000000.0</kp>
    <kd>1000000000000000000000000000.0</kd>
    <mu1>0.8</mu1>
    <mu2>0.8</mu2>
    <material>Gazebo/Black</material>
  </gazebo>
  <!-- Caster Wheel Link (Yaw) -->
  <link name="front_caster_wheel_yaw_link">
    <visual>
      <origin rpy="0 1.5707 1.5707" xyz="0 0 0"/>
      <geometry>
        <cylinder length="0.01" radius="0.02"/>
      </geometry>
      <material name="Red"/>
    </visual>
    <collision>
      <origin rpy="0 1.5707 1.5707" xyz="0 0 0"/>
      <geometry>
        <cylinder length="0.01" radius="0.02"/>
      </geometry>
    </collision>
    <inertial>
      <origin rpy="0 1.5707 1.5707" xyz="0 0 0"/>
      <mass value="0.07"/>
      <inertia ixx="7.583333333333334e-06" ixy="0.0" ixz="0.0" iyy="7.583333333333334e-06" iyz="0.0" izz="1.4000000000000001e-05"/>
    </inertial>
  </link>
  <!-- Yaw Joint -->
  <joint name="front_caster_wheel_yaw_joint" type="continuous">
    <origin rpy="0 1.5707 1.5707" xyz="0.11 0 -0.0775"/>
    <parent link="chassis"/>
    <child link="front_caster_wheel_yaw_link"/>
    <axis xyz="0 0 1"/>
    <limit effort="1000.0" velocity="100.0"/>
    <dynamics damping="0.0" friction="0.1"/>
  </joint>
  <!-- Caster Wheel (Roll) -->
  <link name="front_caster_wheel_roll_link">
    <visual>
      <origin rpy="0 1.5707 1.5707" xyz="0 0 0"/>
      <geometry>
        <cylinder length="0.01" radius="0.02"/>
      </geometry>
      <material name="Green"/>
    </visual>
    <collision>
      <origin rpy="0 1.5707 1.5707" xyz="0 0 0"/>
      <geometry>
        <cylinder length="0.01" radius="0.02"/>
      </geometry>
    </collision>
    <inertial>
      <origin rpy="0 1.5707 1.5707" xyz="0 0 0"/>
      <mass value="0.07"/>
      <inertia ixx="7.583333333333334e-06" ixy="0.0" ixz="0.0" iyy="7.583333333333334e-06" iyz="0.0" izz="1.4000000000000001e-05"/>
    </inertial>
  </link>
  <!-- Roll Joint -->
  <joint name="front_caster_wheel_roll_joint" type="continuous">
    <origin rpy="0 1.5707 1.5707" xyz="0 0 0"/>
    <parent link="front_caster_wheel_yaw_link"/>
    <child link="front_caster_wheel_roll_link"/>
    <axis xyz="1 0 0"/>
    <limit effort="1000.0" velocity="100.0"/>
    <dynamics damping="0.0" friction="0.1"/>
  </joint>
  <!-- Caster Wheel (Pitch) -->
  <link name="front_caster_wheel_pitch_link">
    <visual>
      <origin rpy="0 1.5707 1.5707" xyz="0 0 0"/>
      <geometry>
        <sphere radius="0.02"/>
      </geometry>
      <material name="Yellow"/>
    </visual>
    <collision>
      <origin rpy="0 1.5707 1.5707" xyz="0 0 0"/>
      <geometry>
        <sphere radius="0.02"/>
      </geometry>
    </collision>
    <inertial>
      <origin rpy="0 1.5707 1.5707" xyz="0 0 0"/>
      <mass value="0.07"/>
      <inertia ixx="1.1200000000000003e-05" ixy="0.0" ixz="0.0" iyy="1.1200000000000003e-05" iyz="0.0" izz="1.1200000000000003e-05"/>
    </inertial>
  </link>
  <!-- Pitch Joint -->
  <joint name="front_caster_wheel_pitch_joint" type="continuous">
    <origin rpy="0 1.5707 1.5707" xyz="0 0 0"/>
    <parent link="front_caster_wheel_roll_link"/>
    <child link="front_caster_wheel_pitch_link"/>
    <axis xyz="0 1 0"/>
    <limit effort="1000.0" velocity="100.0"/>
    <dynamics damping="0.0" friction="0.1"/>
  </joint>
  <!-- Caster Wheel Link (Yaw) -->
  <link name="back_caster_wheel_yaw_link">
    <visual>
      <origin rpy="0 1.5707 1.5707" xyz="0 0 0"/>
      <geometry>
        <cylinder length="0.01" radius="0.02"/>
      </geometry>
      <material name="Red"/>
    </visual>
    <collision>
      <origin rpy="0 1.5707 1.5707" xyz="0 0 0"/>
      <geometry>
        <cylinder length="0.01" radius="0.02"/>
      </geometry>
    </collision>
    <inertial>
      <origin rpy="0 1.5707 1.5707" xyz="0 0 0"/>
      <mass value="0.07"/>
      <inertia ixx="7.583333333333334e-06" ixy="0.0" ixz="0.0" iyy="7.583333333333334e-06" iyz="0.0" izz="1.4000000000000001e-05"/>
    </inertial>
  </link>
  <!-- Yaw Joint -->
  <joint name="back_caster_wheel_yaw_joint" type="continuous">
    <origin rpy="0 1.5707 1.5707" xyz="-0.11 0 -0.0775"/>
    <parent link="chassis"/>
    <child link="back_caster_wheel_yaw_link"/>
    <axis xyz="0 0 1"/>
    <limit effort="1000.0" velocity="100.0"/>
    <dynamics damping="0.0" friction="0.1"/>
  </joint>
  <!-- Caster Wheel (Roll) -->
  <link name="back_caster_wheel_roll_link">
    <visual>
      <origin rpy="0 1.5707 1.5707" xyz="0 0 0"/>
      <geometry>
        <cylinder length="0.01" radius="0.02"/>
      </geometry>
      <material name="Green"/>
    </visual>
    <collision>
      <origin rpy="0 1.5707 1.5707" xyz="0 0 0"/>
      <geometry>
        <cylinder length="0.01" radius="0.02"/>
      </geometry>
    </collision>
    <inertial>
      <origin rpy="0 1.5707 1.5707" xyz="0 0 0"/>
      <mass value="0.07"/>
      <inertia ixx="7.583333333333334e-06" ixy="0.0" ixz="0.0" iyy="7.583333333333334e-06" iyz="0.0" izz="1.4000000000000001e-05"/>
    </inertial>
  </link>
  <!-- Roll Joint -->
  <joint name="back_caster_wheel_roll_joint" type="continuous">
    <origin rpy="0 1.5707 1.5707" xyz="0 0 0"/>
    <parent link="back_caster_wheel_yaw_link"/>
    <child link="back_caster_wheel_roll_link"/>
    <axis xyz="1 0 0"/>
    <limit effort="1000.0" velocity="100.0"/>
    <dynamics damping="0.0" friction="0.1"/>
  </joint>
  <!-- Caster Wheel (Pitch) -->
  <link name="back_caster_wheel_pitch_link">
    <visual>
      <origin rpy="0 1.5707 1.5707" xyz="0 0 0"/>
      <geometry>
        <sphere radius="0.02"/>
      </geometry>
      <material name="Yellow"/>
    </visual>
    <collision>
      <origin rpy="0 1.5707 1.5707" xyz="0 0 0"/>
      <geometry>
        <sphere radius="0.02"/>
      </geometry>
    </collision>
    <inertial>
      <origin rpy="0 1.5707 1.5707" xyz="0 0 0"/>
      <mass value="0.07"/>
      <inertia ixx="1.1200000000000003e-05" ixy="0.0" ixz="0.0" iyy="1.1200000000000003e-05" iyz="0.0" izz="1.1200000000000003e-05"/>
    </inertial>
  </link>

  <!-- Pitch Joint -->
  <joint name="back_caster_wheel_pitch_joint" type="continuous">
    <origin rpy="0 1.5707 1.5707" xyz="0 0 0"/>
    <parent link="back_caster_wheel_roll_link"/>
    <child link="back_caster_wheel_pitch_link"/>
    <axis xyz="0 1 0"/>
    <limit effort="1000.0" velocity="100.0"/>
    <dynamics damping="0.0" friction="0.1"/>
  </joint>
  
  <!-- Gazebo configuration for Caster Wheels -->
  <gazebo reference="front_caster_wheel_yaw_link">
    <material>Gazebo/Red</material>
  </gazebo>
  <gazebo reference="back_caster_wheel_yaw_link">
    <material>Gazebo/Red</material>
  </gazebo>
  <gazebo reference="front_caster_wheel_roll_link">
    <material>Gazebo/Green</material>
  </gazebo>
  <gazebo reference="back_caster_wheel_roll_link">
    <material>Gazebo/Green</material>
  </gazebo>

  <gazebo reference="front_caster_wheel_pitch_link">
    <kp>1000000000000000000000000000.0</kp>
    <kd>1000000000000000000000000000.0</kd>
    <mu1>0.5</mu1>
    <mu2>0.5</mu2>
    <material>Gazebo/Yellow</material>
  </gazebo>
  <gazebo reference="back_caster_wheel_pitch_link">
    <kp>1000000000000000000000000000.0</kp>
    <kd>1000000000000000000000000000.0</kd>
    <mu1>0.5</mu1>
    <mu2>0.5</mu2>
    <material>Gazebo/Yellow</material>
  </gazebo>

  <!-- Plugin -->
  <!-- Joint State Publisher -->
  <gazebo>
    <plugin name="barista_robot_joint_state" filename="libgazebo_ros_joint_state_publisher.so">
      <ros>
        <remapping>~/out:=joint_state</remapping>
      </ros>
      <update_rate>30</update_rate>
      <joint_name>wheel_left_joint</joint_name>
      <joint_name>wheel_right_joint</joint_name>
      <joint_name>front_caster_wheel_yaw_joint</joint_name>
      <joint_name>back_caster_wheel_yaw_joint</joint_name>
      <joint_name>front_caster_wheel_roll_joint</joint_name>
      <joint_name>back_caster_wheel_roll_joint</joint_name>
      <joint_name>front_caster_wheel_pitch_joint</joint_name>
      <joint_name>back_caster_wheel_pitch_joint</joint_name>
    </plugin>
  </gazebo>
  <!-- Differential Drive Plugin -->
  <gazebo>
    <plugin name="differential_drive_controller" filename="libgazebo_ros_diff_drive.so">
      <ros>
        <remapping>/out:=cmd_vel</remapping>
      </ros>

      <!-- Wheels -->
      <left_joint>wheel_left_joint</left_joint>
      <right_joint>wheel_right_joint</right_joint>
      <!-- Kinematics -->
      <wheel_separation>0.24</wheel_separation>
      <wheel_diameter>0.0704</wheel_diameter>
      <!-- Limits -->
      <max_wheel_torque>0.5</max_wheel_torque>
      <max_wheel_acceleration>2.0</max_wheel_acceleration>
      <!-- Output -->
      <publish_odom>true</publish_odom>
      <publish_odom_tf>true</publish_odom_tf>
      <odometry_frame>odom</odometry_frame>
      <robot_base_frame>base_link</robot_base_frame>
    </plugin>
  </gazebo>

  <xacro:if value="${include_laser}">
    <xacro:laser_scanner
      name="lidar"
      color="Gray"
      width="${box_laser_scan_width}"
      height="${box_laser_scan_height}"
      depth="${box_laser_scan_depth}"
      mass="0.05"
      parent_link="chassis"
      xyz="0.12 0 0.125"
      rpy="0 0 0"
      joint_type="fixed"
      axis="0 0 0"/>
  </xacro:if>
    
    <!-- Gazebo Configuration for Laser -->
  <xacro:if value= "${include_laser}">
    <gazebo reference="lidar">
      <material>Gazebo/Gray</material>
    </gazebo>
  </xacro:if>

</robot>