<?xml version="1.0" ?>
<!-- =================================================================================== -->
<!-- |    This document was autogenerated by xacro from barista_robot_model.xacro      | -->
<!-- |    EDITING THIS FILE BY HAND IS NOT RECOMMENDED                                 | -->
<!-- =================================================================================== -->
<robot name="barista_robot">
  <!-- Global Material Definitions -->
  <material name="Red">
    <color rgba="1.0 0.0 0.0 1.0"/>
  </material>
  <material name="Blue">
    <color rgba="0.0 0.0 1.0 1.0"/>
  </material>
  <material name="Black">
    <color rgba="0.0 0.0 0.0 1.0"/>
  </material>
  <material name="Green">
    <color rgba="0.0 1.0 0.0 1.0"/>
  </material>
  <material name="LightNavyBlue">
    <color rgba="0.2 0.2 0.7 1.0"/>
  </material>
  <material name="Gray">
    <color rgba="0.5 0.5 0.5 1.0"/>
  </material>
  <material name="White">
    <color rgba="1.0 1.0 1.0 1.0"/>
  </material>
  <material name="Purple">
    <color rgba="0.5 0.0 0.5 1.0"/>
  </material>
  <material name="Yellow">
    <color rgba="1.0 1.0 0.0 1.0"/>
  </material>
  <!-- Define base_link with visual, collision, and inertial properties -->
  <link name="base_link">
    <!-- Optionally add visual, collision, and inertial properties if needed -->
  </link>
  <!-- Cylindrical Link -->
  <link name="chassis">
    <visual>
      <geometry>
        <cylinder length="0.155" radius="0.178"/>
      </geometry>
      <material name="LightNavyBlue"/>
    </visual>
    <collision>
      <geometry>
        <cylinder length="0.155" radius="0.178"/>
      </geometry>
    </collision>
    <inertial>
      <mass value="0.5"/>
      <origin xyz="0 0 0"/>
      <inertia ixx="0.004961541666666666" ixy="0.0" ixz="0.0" iyy="0.004961541666666666" iyz="0.0" izz="0.007921"/>
    </inertial>
  </link>
  <!-- Joint to Attach to Parent -->
  <joint name="chassis_joint" type="fixed">
    <origin rpy="0 0 0" xyz="0 0 0.0975"/>
    <parent link="base_link"/>
    <child link="chassis"/>
  </joint>
  <gazebo reference="chassis">
    <material>Gazebo/Blue</material>
  </gazebo>
  <!-- Cylindrical Link -->
  <link name="cup_holder_tray">
    <visual>
      <geometry>
        <cylinder length="0.09" radius="0.16"/>
      </geometry>
      <material name="LightNavyBlue"/>
    </visual>
    <collision>
      <geometry>
        <cylinder length="0.09" radius="0.16"/>
      </geometry>
    </collision>
    <inertial>
      <mass value="0.2"/>
      <origin xyz="0 0 0"/>
      <inertia ixx="0.001415" ixy="0.0" ixz="0.0" iyy="0.001415" iyz="0.0" izz="0.00256"/>
    </inertial>
  </link>
  <!-- Joint to Attach to Parent -->
  <joint name="cup_holder_tray_joint" type="fixed">
    <origin rpy="0 0 0" xyz="0 0 0.3425"/>
    <parent link="chassis"/>
    <child link="cup_holder_tray"/>
  </joint>
  <gazebo reference="cup_holder_tray">
    <material>Gazebo/Blue</material>
  </gazebo>
  <!-- Cylindrical Link -->
  <link name="standoff_rod_1">
    <visual>
      <geometry>
        <cylinder length="0.22" radius="0.01"/>
      </geometry>
      <material name="White"/>
    </visual>
    <collision>
      <geometry>
        <cylinder length="0.22" radius="0.01"/>
      </geometry>
    </collision>
    <inertial>
      <mass value="0.07"/>
      <origin xyz="0 0 0"/>
      <inertia ixx="0.00028408333333333334" ixy="0.0" ixz="0.0" iyy="0.00028408333333333334" iyz="0.0" izz="3.5000000000000004e-06"/>
    </inertial>
  </link>
  <!-- Joint to Attach to Parent -->
  <joint name="standoff_rod_1_joint" type="fixed">
    <origin rpy="0 0 0" xyz="0.05 0.12 0.1875"/>
    <parent link="chassis"/>
    <child link="standoff_rod_1"/>
  </joint>
  <!-- Cylindrical Link -->
  <link name="standoff_rod_2">
    <visual>
      <geometry>
        <cylinder length="0.22" radius="0.01"/>
      </geometry>
      <material name="White"/>
    </visual>
    <collision>
      <geometry>
        <cylinder length="0.22" radius="0.01"/>
      </geometry>
    </collision>
    <inertial>
      <mass value="0.07"/>
      <origin xyz="0 0 0"/>
      <inertia ixx="0.00028408333333333334" ixy="0.0" ixz="0.0" iyy="0.00028408333333333334" iyz="0.0" izz="3.5000000000000004e-06"/>
    </inertial>
  </link>
  <!-- Joint to Attach to Parent -->
  <joint name="standoff_rod_2_joint" type="fixed">
    <origin rpy="0 0 0" xyz="-0.05 0.12 0.1875"/>
    <parent link="chassis"/>
    <child link="standoff_rod_2"/>
  </joint>
  <!-- Cylindrical Link -->
  <link name="standoff_rod_3">
    <visual>
      <geometry>
        <cylinder length="0.22" radius="0.01"/>
      </geometry>
      <material name="White"/>
    </visual>
    <collision>
      <geometry>
        <cylinder length="0.22" radius="0.01"/>
      </geometry>
    </collision>
    <inertial>
      <mass value="0.07"/>
      <origin xyz="0 0 0"/>
      <inertia ixx="0.00028408333333333334" ixy="0.0" ixz="0.0" iyy="0.00028408333333333334" iyz="0.0" izz="3.5000000000000004e-06"/>
    </inertial>
  </link>
  <!-- Joint to Attach to Parent -->
  <joint name="standoff_rod_3_joint" type="fixed">
    <origin rpy="0 0 0" xyz="0.05 -0.12 0.1875"/>
    <parent link="chassis"/>
    <child link="standoff_rod_3"/>
  </joint>
  <!-- Cylindrical Link -->
  <link name="standoff_rod_4">
    <visual>
      <geometry>
        <cylinder length="0.22" radius="0.01"/>
      </geometry>
      <material name="White"/>
    </visual>
    <collision>
      <geometry>
        <cylinder length="0.22" radius="0.01"/>
      </geometry>
    </collision>
    <inertial>
      <mass value="0.07"/>
      <origin xyz="0 0 0"/>
      <inertia ixx="0.00028408333333333334" ixy="0.0" ixz="0.0" iyy="0.00028408333333333334" iyz="0.0" izz="3.5000000000000004e-06"/>
    </inertial>
  </link>
  <!-- Joint to Attach to Parent -->
  <joint name="standoff_rod_4_joint" type="fixed">
    <origin rpy="0 0 0" xyz="-0.05 -0.12 0.1875"/>
    <parent link="chassis"/>
    <child link="standoff_rod_4"/>
  </joint>
  <gazebo reference="standoff_rod_1">
    <material>Gazebo/White</material>
  </gazebo>
  <gazebo reference="standoff_rod_2">
    <material>Gazebo/White</material>
  </gazebo>
  <gazebo reference="standoff_rod_3">
    <material>Gazebo/White</material>
  </gazebo>
  <gazebo reference="standoff_rod_4">
    <material>Gazebo/White</material>
  </gazebo>
  <!-- Cylindrical Link -->
  <link name="wheel_right">
    <visual>
      <geometry>
        <cylinder length="0.0206" radius="0.0352"/>
      </geometry>
      <material name="Black"/>
    </visual>
    <collision>
      <geometry>
        <cylinder length="0.0206" radius="0.0352"/>
      </geometry>
    </collision>
    <inertial>
      <mass value="0.1"/>
      <origin xyz="0 0 0"/>
      <inertia ixx="3.451233333333334e-05" ixy="0.0" ixz="0.0" iyy="3.451233333333334e-05" iyz="0.0" izz="6.1952e-05"/>
    </inertial>
  </link>
  <!-- Joint to Attach to Parent -->
  <joint name="wheel_right_joint" type="continuous">
    <origin rpy="0 1.5708 1.5708" xyz="0 -0.12 -0.0623"/>
    <parent link="chassis"/>
    <child link="wheel_right"/>
    <axis xyz="0 0 1"/>
  </joint>
  <!-- Cylindrical Link -->
  <link name="wheel_left">
    <visual>
      <geometry>
        <cylinder length="0.0206" radius="0.0352"/>
      </geometry>
      <material name="Black"/>
    </visual>
    <collision>
      <geometry>
        <cylinder length="0.0206" radius="0.0352"/>
      </geometry>
    </collision>
    <inertial>
      <mass value="0.1"/>
      <origin xyz="0 0 0"/>
      <inertia ixx="3.451233333333334e-05" ixy="0.0" ixz="0.0" iyy="3.451233333333334e-05" iyz="0.0" izz="6.1952e-05"/>
    </inertial>
  </link>
  <!-- Joint to Attach to Parent -->
  <joint name="wheel_left_joint" type="continuous">
    <origin rpy="0 1.5708 1.5708" xyz="0 0.12 -0.0623"/>
    <parent link="chassis"/>
    <child link="wheel_left"/>
    <axis xyz="0 0 1"/>
  </joint>
  <!-- Gazebo configuration for Wheels -->
  <gazebo reference="wheel_right">
    <kp>1000000000000000000000000000.0</kp>
    <kd>1000000000000000000000000000.0</kd>
    <mu1>0.8</mu1>
    <mu2>0.8</mu2>
    <material>Gazebo/Black</material>
  </gazebo>
  <gazebo reference="wheel_left">
    <kp>1000000000000000000000000000.0</kp>
    <kd>1000000000000000000000000000.0</kd>
    <mu1>0.8</mu1>
    <mu2>0.8</mu2>
    <material>Gazebo/Black</material>
  </gazebo>
  <!-- Caster Wheel Link (Yaw) -->
  <link name="front_caster_wheel_yaw_link">
    <visual>
      <origin rpy="0 1.5707 1.5707" xyz="0 0 0"/>
      <geometry>
        <cylinder length="0.01" radius="0.02"/>
      </geometry>
      <material name="Red"/>
    </visual>
    <collision>
      <origin rpy="0 1.5707 1.5707" xyz="0 0 0"/>
      <geometry>
        <cylinder length="0.01" radius="0.02"/>
      </geometry>
    </collision>
    <inertial>
      <origin rpy="0 1.5707 1.5707" xyz="0 0 0"/>
      <mass value="0.07"/>
      <inertia ixx="7.583333333333334e-06" ixy="0.0" ixz="0.0" iyy="7.583333333333334e-06" iyz="0.0" izz="1.4000000000000001e-05"/>
    </inertial>
  </link>
  <!-- Yaw Joint -->
  <joint name="front_caster_wheel_yaw_joint" type="continuous">
    <origin rpy="0 1.5707 1.5707" xyz="0.11 0 -0.0775"/>
    <parent link="chassis"/>
    <child link="front_caster_wheel_yaw_link"/>
    <axis xyz="0 0 1"/>
    <limit effort="1000.0" velocity="100.0"/>
    <dynamics damping="0.0" friction="0.1"/>
  </joint>
  <!-- Caster Wheel (Roll) -->
  <link name="front_caster_wheel_roll_link">
    <visual>
      <origin rpy="0 1.5707 1.5707" xyz="0 0 0"/>
      <geometry>
        <cylinder length="0.01" radius="0.02"/>
      </geometry>
      <material name="Green"/>
    </visual>
    <collision>
      <origin rpy="0 1.5707 1.5707" xyz="0 0 0"/>
      <geometry>
        <cylinder length="0.01" radius="0.02"/>
      </geometry>
    </collision>
    <inertial>
      <origin rpy="0 1.5707 1.5707" xyz="0 0 0"/>
      <mass value="0.07"/>
      <inertia ixx="7.583333333333334e-06" ixy="0.0" ixz="0.0" iyy="7.583333333333334e-06" iyz="0.0" izz="1.4000000000000001e-05"/>
    </inertial>
  </link>
  <!-- Roll Joint -->
  <joint name="front_caster_wheel_roll_joint" type="continuous">
    <origin rpy="0 1.5707 1.5707" xyz="0 0 0"/>
    <parent link="front_caster_wheel_yaw_link"/>
    <child link="front_caster_wheel_roll_link"/>
    <axis xyz="1 0 0"/>
    <limit effort="1000.0" velocity="100.0"/>
    <dynamics damping="0.0" friction="0.1"/>
  </joint>
  <!-- Caster Wheel (Pitch) -->
  <link name="front_caster_wheel_pitch_link">
    <visual>
      <origin rpy="0 1.5707 1.5707" xyz="0 0 0"/>
      <geometry>
        <sphere radius="0.02"/>
      </geometry>
      <material name="Yellow"/>
    </visual>
    <collision>
      <origin rpy="0 1.5707 1.5707" xyz="0 0 0"/>
      <geometry>
        <sphere radius="0.02"/>
      </geometry>
    </collision>
    <inertial>
      <origin rpy="0 1.5707 1.5707" xyz="0 0 0"/>
      <mass value="0.07"/>
      <inertia ixx="1.1200000000000003e-05" ixy="0.0" ixz="0.0" iyy="1.1200000000000003e-05" iyz="0.0" izz="1.1200000000000003e-05"/>
    </inertial>
  </link>
  <!-- Pitch Joint -->
  <joint name="front_caster_wheel_pitch_joint" type="continuous">
    <origin rpy="0 1.5707 1.5707" xyz="0 0 0"/>
    <parent link="front_caster_wheel_roll_link"/>
    <child link="front_caster_wheel_pitch_link"/>
    <axis xyz="0 1 0"/>
    <limit effort="1000.0" velocity="100.0"/>
    <dynamics damping="0.0" friction="0.1"/>
  </joint>
  <!-- Caster Wheel Link (Yaw) -->
  <link name="back_caster_wheel_yaw_link">
    <visual>
      <origin rpy="0 1.5707 1.5707" xyz="0 0 0"/>
      <geometry>
        <cylinder length="0.01" radius="0.02"/>
      </geometry>
      <material name="Red"/>
    </visual>
    <collision>
      <origin rpy="0 1.5707 1.5707" xyz="0 0 0"/>
      <geometry>
        <cylinder length="0.01" radius="0.02"/>
      </geometry>
    </collision>
    <inertial>
      <origin rpy="0 1.5707 1.5707" xyz="0 0 0"/>
      <mass value="0.07"/>
      <inertia ixx="7.583333333333334e-06" ixy="0.0" ixz="0.0" iyy="7.583333333333334e-06" iyz="0.0" izz="1.4000000000000001e-05"/>
    </inertial>
  </link>
  <!-- Yaw Joint -->
  <joint name="back_caster_wheel_yaw_joint" type="continuous">
    <origin rpy="0 1.5707 1.5707" xyz="-0.11 0 -0.0775"/>
    <parent link="chassis"/>
    <child link="back_caster_wheel_yaw_link"/>
    <axis xyz="0 0 1"/>
    <limit effort="1000.0" velocity="100.0"/>
    <dynamics damping="0.0" friction="0.1"/>
  </joint>
  <!-- Caster Wheel (Roll) -->
  <link name="back_caster_wheel_roll_link">
    <visual>
      <origin rpy="0 1.5707 1.5707" xyz="0 0 0"/>
      <geometry>
        <cylinder length="0.01" radius="0.02"/>
      </geometry>
      <material name="Green"/>
    </visual>
    <collision>
      <origin rpy="0 1.5707 1.5707" xyz="0 0 0"/>
      <geometry>
        <cylinder length="0.01" radius="0.02"/>
      </geometry>
    </collision>
    <inertial>
      <origin rpy="0 1.5707 1.5707" xyz="0 0 0"/>
      <mass value="0.07"/>
      <inertia ixx="7.583333333333334e-06" ixy="0.0" ixz="0.0" iyy="7.583333333333334e-06" iyz="0.0" izz="1.4000000000000001e-05"/>
    </inertial>
  </link>
  <!-- Roll Joint -->
  <joint name="back_caster_wheel_roll_joint" type="continuous">
    <origin rpy="0 1.5707 1.5707" xyz="0 0 0"/>
    <parent link="back_caster_wheel_yaw_link"/>
    <child link="back_caster_wheel_roll_link"/>
    <axis xyz="1 0 0"/>
    <limit effort="1000.0" velocity="100.0"/>
    <dynamics damping="0.0" friction="0.1"/>
  </joint>
  <!-- Caster Wheel (Pitch) -->
  <link name="back_caster_wheel_pitch_link">
    <visual>
      <origin rpy="0 1.5707 1.5707" xyz="0 0 0"/>
      <geometry>
        <sphere radius="0.02"/>
      </geometry>
      <material name="Yellow"/>
    </visual>
    <collision>
      <origin rpy="0 1.5707 1.5707" xyz="0 0 0"/>
      <geometry>
        <sphere radius="0.02"/>
      </geometry>
    </collision>
    <inertial>
      <origin rpy="0 1.5707 1.5707" xyz="0 0 0"/>
      <mass value="0.07"/>
      <inertia ixx="1.1200000000000003e-05" ixy="0.0" ixz="0.0" iyy="1.1200000000000003e-05" iyz="0.0" izz="1.1200000000000003e-05"/>
    </inertial>
  </link>
  <!-- Pitch Joint -->
  <joint name="back_caster_wheel_pitch_joint" type="continuous">
    <origin rpy="0 1.5707 1.5707" xyz="0 0 0"/>
    <parent link="back_caster_wheel_roll_link"/>
    <child link="back_caster_wheel_pitch_link"/>
    <axis xyz="0 1 0"/>
    <limit effort="1000.0" velocity="100.0"/>
    <dynamics damping="0.0" friction="0.1"/>
  </joint>
  <!-- Gazebo configuration for Caster Wheels -->
  <gazebo reference="front_caster_wheel_yaw_link">
    <material>Gazebo/Red</material>
  </gazebo>
  <gazebo reference="back_caster_wheel_yaw_link">
    <material>Gazebo/Red</material>
  </gazebo>
  <gazebo reference="front_caster_wheel_roll_link">
    <material>Gazebo/Green</material>
  </gazebo>
  <gazebo reference="back_caster_wheel_roll_link">
    <material>Gazebo/Green</material>
  </gazebo>
  <gazebo reference="front_caster_wheel_pitch_link">
    <kp>1000000000000000000000000000.0</kp>
    <kd>1000000000000000000000000000.0</kd>
    <mu1>0.5</mu1>
    <mu2>0.5</mu2>
    <material>Gazebo/Yellow</material>
  </gazebo>
  <gazebo reference="back_caster_wheel_pitch_link">
    <kp>1000000000000000000000000000.0</kp>
    <kd>1000000000000000000000000000.0</kd>
    <mu1>0.5</mu1>
    <mu2>0.5</mu2>
    <material>Gazebo/Yellow</material>
  </gazebo>
  <!-- Plugin -->
  <!-- Joint State Publisher -->
  <gazebo>
    <plugin filename="libgazebo_ros_joint_state_publisher.so" name="barista_robot_joint_state">
      <ros>
        <remapping>~/out:=joint_state</remapping>
      </ros>
      <update_rate>30</update_rate>
      <joint_name>wheel_left_joint</joint_name>
      <joint_name>wheel_right_joint</joint_name>
      <joint_name>front_caster_wheel_yaw_joint</joint_name>
      <joint_name>back_caster_wheel_yaw_joint</joint_name>
      <joint_name>front_caster_wheel_roll_joint</joint_name>
      <joint_name>back_caster_wheel_roll_joint</joint_name>
      <joint_name>front_caster_wheel_pitch_joint</joint_name>
      <joint_name>back_caster_wheel_pitch_joint</joint_name>
    </plugin>
  </gazebo>
  <!-- Differential Drive Plugin -->
  <gazebo>
    <plugin filename="libgazebo_ros_diff_drive.so" name="differential_drive_controller">
      <!-- Wheels -->
      <left_joint>wheel_left_joint</left_joint>
      <right_joint>wheel_right_joint</right_joint>
      <!-- Kinematics -->
      <wheel_separation>0.24</wheel_separation>
      <wheel_diameter>0.0704</wheel_diameter>
      <!-- Limits -->
      <max_wheel_torque>0.5</max_wheel_torque>
      <max_wheel_acceleration>2.0</max_wheel_acceleration>
      <!-- Output -->
      <publish_odom>true</publish_odom>
      <publish_odom_tf>true</publish_odom_tf>
      <odometry_frame>odom</odometry_frame>
      <robot_base_frame>base_link</robot_base_frame>
    </plugin>
  </gazebo>
  <link name="lidar">
    <visual>
      <origin rpy="0 0 0" xyz="0 0 -0.05"/>
      <geometry>
        <mesh filename="package://barista_robot_description/meshes/hokuyo_urg_04lx.dae"/>
      </geometry>
      <material name="Gray"/>
    </visual>
    <collision>
      <origin rpy="0 0 0" xyz="0 0 0"/>
      <geometry>
        <mesh filename="package://barista_robot_description/meshes/hokuyo_urg_04lx.dae"/>
      </geometry>
    </collision>
    <inertial>
      <mass value="0.05"/>
      <origin xyz="0 0 0"/>
      <inertia ixx="1.5520833333333336e-05" ixy="0.0" ixz="0.0" iyy="1.0208333333333335e-05" iyz="0.0" izz="1.5520833333333336e-05"/>
    </inertial>
  </link>
  <joint name="lidar_joint" type="fixed">
    <origin rpy="0 0 0" xyz="0.12 0 0.125"/>
    <parent link="chassis"/>
    <child link="lidar"/>
  </joint>
  <!-- Laser Sensor Plugin -->
  <gazebo reference="lidar">
    <sensor name="sensor_ray" type="ray">
      <pose>0 0 0 0 0 0</pose>
      <ray>
        <scan>
          <horizontal>
            <samples>200</samples>
            <resolution>1.0</resolution>
            <min_angle>-3.14</min_angle>
            <max_angle>3.14</max_angle>
          </horizontal>
        </scan>
        <range>
          <min>0.1</min>
          <max>5.0</max>
        </range>
      </ray>
      <visualize>true</visualize>
      <always_on>true</always_on>
      <update_rate>100.0</update_rate>
      <plugin filename="libgazebo_ros_ray_sensor.so" name="laser">
        <ros>
          <namespace>/barista_robot</namespace>
          <remapping>~/out:=scan</remapping>
        </ros>
        <output_type>sensor_msgs/LaserScan</output_type>
      </plugin>
    </sensor>
  </gazebo>
  <gazebo reference="lidar">
    <material>Gazebo/Gray</material>
  </gazebo>
</robot>
